<?xml version="1.0" ?>
<!-- =================================================================================== -->
<!-- |    This document was autogenerated by xacro from robot_urdf.xacro               | -->
<!-- |    EDITING THIS FILE BY HAND IS NOT RECOMMENDED                                 | -->
<!-- =================================================================================== -->
<xacro:macro name="robot_urdf">
  <link name="hand_base_link">
    <inertial>
      <origin rpy="0 0 0" xyz="-0.00005520 1.2341E-05 0.03296193"/>
      <mass value="0.25641368"/>
      <inertia ixx="4.6351E-04" ixy="-1.0E-08" ixz="-1.04E-06" iyy="4.4525E-04" iyz="-5.00E-08" izz="1.0438E-04"/>
    </inertial>
    <visual>
      <origin rpy="0 0 0" xyz="0 0 0"/>
      <geometry>
        <mesh filename="file:///home/lzh/ros1_ws/src/rm_robot/rm_description/meshes/Gripper/hand_base_link.STL"/>
      </geometry>
      <material name="">
        <color rgba="0.89804 0.91765 0.92941 1"/>
      </material>
    </visual>
  </link>
  <link name="hand_narrow1_Link">
    <inertial>
      <origin rpy="0 0 0" xyz="0.0094685 0.0068806 6.5437E-05"/>
      <mass value="0.025428"/>
      <inertia ixx="1.9574E-06" ixy="-4.2911E-07" ixz="-3.7111E-11" iyy="2.3919E-06" iyz="-3.008E-10" izz="1.5501E-06"/>
    </inertial>
    <visual>
      <origin rpy="0 0 0" xyz="0 0 0"/>
      <geometry>
        <mesh filename="package://robot_description/meshes/narrow1_Link.STL"/>
      </geometry>
      <material name="">
        <color rgba="0.75294 0.75294 0.75294 1"/>
      </material>
    </visual>
    <collision>
      <origin rpy="0 0 0" xyz="0 0 0"/>
      <geometry>
        <mesh filename="package://robot_description/meshes/narrow1_Link.STL"/>
      </geometry>
    </collision>
  </link>
  <joint name="hand_narrow1_joint" type="revolute">
    <origin rpy="-2.9951 -1.5708 -0.15964" xyz="0 -0.0195 0.0565"/>
    <parent link="base_link"/>
    <child link="hand_narrow1_Link"/>
    <axis xyz="0 0 -1"/>
    <limit effort="0" lower="-3.14" upper="3.14" velocity="0"/>
  </joint>
  <link name="hand_narrow2_Link">
    <inertial>
      <origin rpy="0 0 0" xyz="0.0088027 -0.007035 1.6424E-05"/>
      <mass value="0.0040132"/>
      <inertia ixx="1.0307E-07" ixy="5.7851E-08" ixz="9.5801E-11" iyy="1.1385E-07" iyz="-2.81E-11" izz="1.7009E-07"/>
    </inertial>
    <visual>
      <origin rpy="0 0 0" xyz="0 0 0"/>
      <geometry>
        <mesh filename="package://robot_description/meshes/narrow2_Link.STL"/>
      </geometry>
      <material name="">
        <color rgba="0.75294 0.75294 0.75294 1"/>
      </material>
    </visual>
    <collision>
      <origin rpy="0 0 0" xyz="0 0 0"/>
      <geometry>
        <mesh filename="package://robot_description/meshes/narrow2_Link.STL"/>
      </geometry>
    </collision>
  </link>
  <joint name="hand_narrow2_joint" type="revolute">
    <origin rpy="0 0 0" xyz="0.030852 0.018551 0"/>
    <parent link="hand_narrow1_Link"/>
    <child link="hand_narrow2_Link"/>
    <axis xyz="0 0 -1"/>
    <limit effort="0" lower="-3.14" upper="3.14" velocity="0"/>
  </joint>
  <link name="hand_narrow3_Link">
    <inertial>
      <origin rpy="0 0 0" xyz="0.012508 -0.0079729 9.4339E-05"/>
      <mass value="0.018029"/>
      <inertia ixx="1.1403E-06" ixy="5.5159E-07" ixz="-4.0096E-13" iyy="2.5704E-06" iyz="1.0951E-12" izz="2.3252E-06"/>
    </inertial>
    <visual>
      <origin rpy="0 0 0" xyz="0 0 0"/>
      <geometry>
        <mesh filename="package://robot_description/meshes/narrow3_Link.STL"/>
      </geometry>
      <material name="">
        <color rgba="0.75294 0.75294 0.75294 1"/>
      </material>
    </visual>
    <collision>
      <origin rpy="0 0 0" xyz="0 0 0"/>
      <geometry>
        <mesh filename="package://robot_description/meshes/narrow3_Link.STL"/>
      </geometry>
    </collision>
  </link>
  <joint name="hand_narrow3_joint" type="revolute">
    <origin rpy="0 0 0" xyz="0.018118 -0.01574 0"/>
    <parent link="hand_narrow2_Link"/>
    <child link="hand_narrow3_Link"/>
    <axis xyz="0 0 -1"/>
    <limit effort="0" lower="-3.14" upper="3.14" velocity="0"/>
  </joint>
  <link name="hand_narrow4_Link">
  </link>
  <joint name="hand_narrow4_joint" type="fixed">
    <origin rpy="0 0 0" xyz="0 -0.0104 0"/>
    <parent link="hand_narrow3_Link"/>
    <child link="hand_narrow4_Link"/>
    <axis xyz="0 0 1"/>
    <limit effort="0" lower="-3.14" upper="3.14" velocity="0"/>
  </joint>
  <link name="hand_narrow_loop_Link">
    <inertial>
      <origin rpy="0 0 0" xyz="0.014869 -0.0036066 0.00029307"/>
      <mass value="0.022591"/>
      <inertia ixx="4.3916E-06" ixy="1.114E-07" ixz="-4.9655E-12" iyy="4.737E-06" iyz="1.7121E-11" izz="6.0445E-07"/>
    </inertial>
    <visual>
      <origin rpy="0 0 0" xyz="0 0 0"/>
      <geometry>
        <mesh filename="package://robot_description/meshes/narrow_loop_Link.STL"/>
      </geometry>
      <material name="">
        <color rgba="0.75294 0.75294 0.75294 1"/>
      </material>
    </visual>
    <collision>
      <origin rpy="0 0 0" xyz="0 0 0"/>
      <geometry>
        <mesh filename="package://robot_description/meshes/narrow_loop_Link.STL"/>
      </geometry>
    </collision>
  </link>
  <joint name="hand_narrow_loop_joint" type="revolute">
    <origin rpy="-2.9951 -1.5708 -0.15964" xyz="0 -0.021633 0.07387"/>
    <parent link="base_link"/>
    <child link="hand_narrow_loop_Link"/>
    <axis xyz="0 0 -1"/>
    <limit effort="0" lower="-3.14" upper="3.14" velocity="0"/>
  </joint>
  <link name="hand_wide1_Link">
    <inertial>
      <origin rpy="0 0 0" xyz="0.0095051 -0.0068479 6.8268E-05"/>
      <mass value="0.025428"/>
      <inertia ixx="1.9565E-06" ixy="4.2798E-07" ixz="2.3844E-10" iyy="2.3928E-06" iyz="-1.4454E-10" izz="1.5501E-06"/>
    </inertial>
    <visual>
      <origin rpy="0 0 0" xyz="0 0 0"/>
      <geometry>
        <mesh filename="package://robot_description/meshes/wide1_Link.STL"/>
      </geometry>
      <material name="">
        <color rgba="0.75294 0.75294 0.75294 1"/>
      </material>
    </visual>
    <collision>
      <origin rpy="0 0 0" xyz="0 0 0"/>
      <geometry>
        <mesh filename="package://robot_description/meshes/wide1_Link.STL"/>
      </geometry>
    </collision>
  </link>
  <joint name="hand_wide1_joint" type="revolute">
    <origin rpy="-2.9951 -1.5708 -0.15964" xyz="0 0.0195 0.0565"/>
    <parent link="base_link"/>
    <child link="hand_wide1_Link"/>
    <axis xyz="0 0 -1"/>
    <limit effort="0" lower="-3.14" upper="3.14" velocity="0"/>
  </joint>
  <link name="hand_wide2_Link">
    <inertial>
      <origin rpy="0 0 0" xyz="0.0088027 0.007035 -1.6424E-05"/>
      <mass value="0.0040132"/>
      <inertia ixx="1.0307E-07" ixy="-5.7851E-08" ixz="-9.58E-11" iyy="1.1385E-07" iyz="-2.81E-11" izz="1.7009E-07"/>
    </inertial>
    <visual>
      <origin rpy="0 0 0" xyz="0 0 0"/>
      <geometry>
        <mesh filename="package://robot_description/meshes/wide2_Link.STL"/>
      </geometry>
      <material name="">
        <color rgba="0.75294 0.75294 0.75294 1"/>
      </material>
    </visual>
    <collision>
      <origin rpy="0 0 0" xyz="0 0 0"/>
      <geometry>
        <mesh filename="package://robot_description/meshes/wide2_Link.STL"/>
      </geometry>
    </collision>
  </link>
  <joint name="hand_wide2_joint" type="revolute">
    <origin rpy="0 0 0" xyz="0.030852 -0.018551 0"/>
    <parent link="hand_wide1_Link"/>
    <child link="hand_wide2_Link"/>
    <axis xyz="0 0 -1"/>
    <limit effort="0" lower="-3.14" upper="3.14" velocity="0"/>
  </joint>
  <link name="hand_wide3_Link">
    <inertial>
      <origin rpy="0 0 0" xyz="0.016206 0.0094593 4.7668E-05"/>
      <mass value="0.035835"/>
      <inertia ixx="8.5056E-06" ixy="-1.1363E-06" ixz="-4.2908E-11" iyy="1.1235E-05" iyz="-2.9251E-11" izz="4.6309E-06"/>
    </inertial>
    <visual>
      <origin rpy="0 0 0" xyz="0 0 0"/>
      <geometry>
        <mesh filename="package://robot_description/meshes/wide3_Link.STL"/>
      </geometry>
      <material name="">
        <color rgba="0.75294 0.75294 0.75294 1"/>
      </material>
    </visual>
    <collision>
      <origin rpy="0 0 0" xyz="0 0 0"/>
      <geometry>
        <mesh filename="package://robot_description/meshes/wide3_Link.STL"/>
      </geometry>
    </collision>
  </link>
  <joint name="hand_wide3_joint" type="revolute">
    <origin rpy="0 0 0" xyz="0.018118 0.01574 0"/>
    <parent link="hand_wide2_Link"/>
    <child link="hand_wide3_Link"/>
    <axis xyz="0 0 -1"/>
    <limit effort="0" lower="-3.14" upper="3.14" velocity="0"/>
  </joint>
  <link name="hand_wide4_Link">
  </link>
  <joint name="hand_wide4_joint" type="fixed">
    <origin rpy="0 0 0" xyz="0 0.0104 0"/>
    <parent link="hand_wide3_Link"/>
    <child link="hand_wide4_Link"/>
    <axis xyz="0 0 1"/>
    <limit effort="0" lower="-3.14" upper="3.14" velocity="0"/>
  </joint>
  <link name="hand_wide_loop_Link">
    <inertial>
      <origin rpy="0 0 0" xyz="0.016268 0.0040555 0.00030323"/>
      <mass value="0.025142"/>
      <inertia ixx="5.887E-06" ixy="-1.1234E-07" ixz="2.1954E-11" iyy="6.236E-06" iyz="-9.473E-12" izz="6.2389E-07"/>
    </inertial>
    <visual>
      <origin rpy="0 0 0" xyz="0 0 0"/>
      <geometry>
        <mesh filename="package://robot_description/meshes/wide_loop_Link.STL"/>
      </geometry>
      <material name="">
        <color rgba="0.75294 0.75294 0.75294 1"/>
      </material>
    </visual>
    <collision>
      <origin rpy="0 0 0" xyz="0 0 0"/>
      <geometry>
        <mesh filename="package://robot_description/meshes/wide_loop_Link.STL"/>
      </geometry>
    </collision>
  </link>
  <joint name="hand_wide_loop_joint" type="revolute">
    <origin rpy="-2.9951 -1.5708 -0.15964" xyz="0 0.021633 0.07387"/>
    <parent link="base_link"/>
    <child link="hand_wide_loop_Link"/>
    <axis xyz="0 0 -1"/>
    <limit effort="0" lower="-3.14" upper="3.14" velocity="0"/>
  </joint>
</xacro:macro>

